<?xml version="1.0" ?>
<!-- =================================================================================== -->
<!-- |    This document was autogenerated by xacro from bw_arm.urdf.xacro              | -->
<!-- |    EDITING THIS FILE BY HAND IS NOT RECOMMENDED                                 | -->
<!-- =================================================================================== -->
<robot name="bw_robot_arm" xmlns:xacro="http://ros.org/wiki/xacro">
  <!-- Defining the colors used in this robot -->
  <material name="Black">
    <color rgba="0 0 0 1"/>
  </material>
  <material name="White">
    <color rgba="1 1 1 1"/>
  </material>
  <material name="Blue">
    <color rgba="0 0 1 1"/>
  </material>
  <material name="Red">
    <color rgba="1 0 0 1"/>
  </material>
  <!-- ///////////////////////////////////////   bottom_joint   ////////////////////////////////////////// -->
  <joint name="bottom_joint" type="fixed">
    <origin rpy="0 0 0" xyz="0 0 0"/>
    <parent link="base_link"/>
    <child link="bottom_link"/>
  </joint>
  <link name="bottom_link">
    <visual>
      <origin rpy="0 0 0" xyz=" 0 0 -0.02"/>
      <geometry>
        <box size="1 1 0.02"/>
      </geometry>
      <material name="Black"/>
    </visual>
    <collision>
      <origin rpy="0 0 0" xyz=" 0 0 -0.02"/>
      <geometry>
        <box size="1 1 0.02"/>
      </geometry>
    </collision>
    <inertial>
      <mass value="50"/>
      <inertia ixx="1.0" ixy="0.0" ixz="0.0" iyy="0.5" iyz="0.0" izz="1.0"/>
    </inertial>
  </link>
  <!-- /////////////////////////////////////   BASE LINK    ////////////////////////////////////////////// -->
  <link name="base_link">
    <visual>
      <origin rpy="0 0 0" xyz="0 0 0"/>
      <geometry>
        <cylinder length="0.05" radius="0.064"/>
      </geometry>
      <material name="White"/>
    </visual>
    <collision>
      <origin rpy="0 0 0" xyz="0 0 0"/>
      <geometry>
        <cylinder length="0.05" radius="0.064"/>
      </geometry>
    </collision>
    <inertial>
      <mass value="1"/>
      <inertia ixx="1.0" ixy="0.0" ixz="0.0" iyy="0.5" iyz="0.0" izz="1.0"/>
    </inertial>
  </link>
  <joint name="joint1" type="revolute">
    <parent link="base_link"/>
    <child link="link1"/>
    <origin rpy="0 1.570795 0" xyz="0 0 0.025"/>
    <axis xyz="-1 0 0"/>
    <limit effort="20" lower="-1.57" upper="1.57" velocity="1"/>
    <dynamics damping="50" friction="1"/>
  </joint>
  <!-- /////////////////////////////////////   LINK1  ////////////////////////////////////////////// -->
  <link name="link1">
    <visual>
      <origin rpy="0 1.570795 0" xyz="-0.005 0 0"/>
      <geometry>
        <cylinder length="0.01" radius="0.044"/>
      </geometry>
      <material name="Blue"/>
    </visual>
    <collision>
      <origin rpy="0 1.570795 0" xyz="-0.005 0 0"/>
      <geometry>
        <cylinder length="0.01" radius="0.044"/>
      </geometry>
    </collision>
    <inertial>
      <mass value="1"/>
      <inertia ixx="1.0" ixy="0.0" ixz="0.0" iyy="0.5" iyz="0.0" izz="1.0"/>
    </inertial>
  </link>
  <joint name="joint2" type="revolute">
    <parent link="link1"/>
    <child link="link2"/>
    <origin rpy="-1.570795 0 1.570795" xyz="-0.01 0 0.0"/>
    <axis xyz="1 0 0"/>
    <limit effort="30" lower="-1.57" upper="1.57" velocity="1"/>
    <dynamics damping="50" friction="1"/>
  </joint>
  <!-- ///////////////////////////////////////   LINK2  ////////////////////////////////////////////// -->
  <link name="link2">
    <visual>
      <origin rpy="0 0 0" xyz="0 0 0.06"/>
      <geometry>
        <box size="0.055 0.025 0.12"/>
      </geometry>
      <material name="White"/>
    </visual>
    <collision>
      <origin rpy="0 0 0" xyz="0 0 0.06"/>
      <geometry>
        <box size="0.055 0.025 0.11"/>
      </geometry>
    </collision>
    <inertial>
      <mass value="1"/>
      <inertia ixx="1.0" ixy="0.0" ixz="0.0" iyy="0.5" iyz="0.0" izz="1.0"/>
    </inertial>
  </link>
  <joint name="joint3" type="revolute">
    <parent link="link2"/>
    <child link="link3"/>
    <origin rpy="0 3.14159 0" xyz="0 0 0.12"/>
    <axis xyz="-1 0 0"/>
    <limit effort="30" lower="-1.57" upper="1.57" velocity="1"/>
    <dynamics damping="50" friction="1"/>
  </joint>
  <!-- /////////////////////////////////   LINK3  ///////////////////////////////////////////////////// -->
  <link name="link3">
    <visual>
      <origin rpy="0 0 0" xyz="0 0 -0.05"/>
      <geometry>
        <box size="0.055 0.025 0.10"/>
      </geometry>
      <material name="Blue"/>
    </visual>
    <collision>
      <origin rpy="0 0 0" xyz="0 0 -0.05"/>
      <geometry>
        <box size="0.055 0.025 0.10"/>
      </geometry>
    </collision>
    <inertial>
      <mass value="1"/>
      <inertia ixx="1.0" ixy="0.0" ixz="0.0" iyy="0.5" iyz="0.0" izz="1.0"/>
    </inertial>
  </link>
  <joint name="joint4" type="revolute">
    <parent link="link3"/>
    <child link="link4"/>
    <origin rpy="0 1.570795 3.14159" xyz="0.0 0.0 -0.1"/>
    <axis xyz="0 0 1"/>
    <limit effort="30" lower="-1.57" upper="1.57" velocity="1"/>
    <dynamics damping="50" friction="1"/>
  </joint>
  <link name="link4">
    <visual>
      <origin rpy="0 1.570795 0" xyz="0.022 0 0"/>
      <geometry>
        <box size="0.055 0.025 0.044"/>
      </geometry>
      <material name="Black"/>
    </visual>
    <collision>
      <origin rpy="0 1.570795 0" xyz="0.022 0 0"/>
      <geometry>
        <box size="0.055 0.025 0.044"/>
      </geometry>
    </collision>
    <inertial>
      <mass value="1"/>
      <inertia ixx="1.0" ixy="0.0" ixz="0.0" iyy="0.5" iyz="0.0" izz="1.0"/>
    </inertial>
  </link>
  <joint name="joint5" type="revolute">
    <parent link="link4"/>
    <child link="link5"/>
    <origin rpy="0 1.570795 0" xyz="0.02 0.0 0.0"/>
    <axis xyz="0 0 1"/>
    <limit effort="30" lower="-1.57" upper="1.57" velocity="1"/>
    <dynamics damping="50" friction="1"/>
  </joint>
  <!-- //////////////////////////////////   LINK5  ///////////////////////////////////////////////// -->
  <link name="link5">
    <visual>
      <origin rpy="0 0 0" xyz="0 0 0.01"/>
      <geometry>
        <cylinder length="0.02" radius="0.06"/>
      </geometry>
      <material name="White"/>
    </visual>
    <collision>
      <origin rpy="0 0 0" xyz="0 0 0.01 "/>
      <geometry>
        <cylinder length="0.02" radius="0.06"/>
      </geometry>
    </collision>
    <inertial>
      <mass value="1"/>
      <inertia ixx="1.0" ixy="0.0" ixz="0.0" iyy="0.5" iyz="0.0" izz="1.0"/>
    </inertial>
  </link>
  <joint name="finger_joint1" type="prismatic">
    <parent link="link5"/>
    <child link="gripper_finger_link1"/>
    <origin xyz="-0.01 0 0"/>
    <axis xyz="1 0 0"/>
    <limit effort="10" lower="-0.04" upper="0.01" velocity="1.0"/>
    <dynamics damping="50" friction="1"/>
  </joint>
  <!-- //////////////////////////////////////   gripper   ////////////////////////////////////////////// -->
  <!-- LEFT GRIPPER AFT LINK -->
  <link name="gripper_finger_link1">
    <visual>
      <origin xyz="-0.01 0 0.06"/>
      <geometry>
        <box size="0.01 0.01 0.12"/>
      </geometry>
      <material name="White"/>
    </visual>
    <inertial>
      <mass value="1"/>
      <inertia ixx="1.0" ixy="0.0" ixz="0.0" iyy="0.5" iyz="0.0" izz="1.0"/>
    </inertial>
  </link>
  <!-- RIGHT GRIPPER AFT LINK -->
  <link name="gripper_finger_link2">
    <visual>
      <origin xyz="0.01 0 0.06"/>
      <geometry>
        <box size="0.01 0.01 0.12"/>
      </geometry>
      <material name="Red"/>
    </visual>
    <inertial>
      <mass value="1"/>
      <inertia ixx="1.0" ixy="0.0" ixz="0.0" iyy="0.5" iyz="0.0" izz="1.0"/>
    </inertial>
  </link>
  <joint name="finger_joint2" type="prismatic">
    <parent link="link5"/>
    <child link="gripper_finger_link2"/>
    <origin xyz="0.01 0 0"/>
    <axis xyz="-1 0 0"/>
    <limit effort="10" lower="-0.04" upper="0.01" velocity="1.0"/>
    <dynamics damping="50" friction="1"/>
    <mimic joint="finger_joint1" multiplier="1"/>
  </joint>
  <joint name="grasping_frame_joint" type="fixed">
    <parent link="link5"/>
    <child link="end_effector_link"/>
    <origin rpy="0 0 0" xyz="0 0 0.12"/>
  </joint>
  <!-- end effector link -->
  <link name="end_effector_link">
    <visual>
      <origin rpy="0 0 0" xyz="0 0 0"/>
      <geometry>
        <box size="0.001 0.001 0.001"/>
      </geometry>
      <material name="Red"/>
    </visual>
    <inertial>
      <mass value="0.01"/>
      <inertia ixx="1.0" ixy="0.0" ixz="0.0" iyy="0.5" iyz="0.0" izz="1.0"/>
    </inertial>
  </link>
  <!-- /////////////////////////////////   Gazebo   ////////////////////////////////////// -->
  <gazebo reference="bottom_link">
    <material>Gazebo/White</material>
  </gazebo>
  <gazebo reference="base_link">
    <material>Gazebo/White</material>
  </gazebo>
  <gazebo reference="link1">
    <material>Gazebo/Blue</material>
  </gazebo>
  <gazebo reference="link2">
    <material>Gazebo/White</material>
  </gazebo>
  <gazebo reference="link3">
    <material>Gazebo/Blue</material>
  </gazebo>
  <gazebo reference="link4">
    <material>Gazebo/Black</material>
  </gazebo>
  <gazebo reference="link5">
    <material>Gazebo/Red</material>
  </gazebo>
  <gazebo reference="gripper_finger_link1">
    <material>Gazebo/White</material>
  </gazebo>
  <gazebo reference="gripper_finger_link2">
    <material>Gazebo/White</material>
  </gazebo>
  <!-- end effector link -->
  <gazebo reference="end_effector_link">
    <material>Gazebo/Red</material>
  </gazebo>
  <transmission name="tran1">
    <type>transmission_interface/SimpleTransmission</type>
    <joint name="joint1">
      <hardwareInterface>hardware_interface/PositionJointInterface</hardwareInterface>
    </joint>
    <actuator name="motor1">
      <hardwareInterface>hardware_interface/PositionJointInterface</hardwareInterface>
      <mechanicalReduction>1</mechanicalReduction>
    </actuator>
  </transmission>
  <transmission name="tran1">
    <type>transmission_interface/SimpleTransmission</type>
    <joint name="joint2">
      <hardwareInterface>hardware_interface/PositionJointInterface</hardwareInterface>
    </joint>
    <actuator name="motor1">
      <hardwareInterface>hardware_interface/PositionJointInterface</hardwareInterface>
      <mechanicalReduction>1</mechanicalReduction>
    </actuator>
  </transmission>
  <transmission name="tran1">
    <type>transmission_interface/SimpleTransmission</type>
    <joint name="joint3">
      <hardwareInterface>hardware_interface/PositionJointInterface</hardwareInterface>
    </joint>
    <actuator name="motor1">
      <hardwareInterface>hardware_interface/PositionJointInterface</hardwareInterface>
      <mechanicalReduction>1</mechanicalReduction>
    </actuator>
  </transmission>
  <transmission name="tran1">
    <type>transmission_interface/SimpleTransmission</type>
    <joint name="joint4">
      <hardwareInterface>hardware_interface/PositionJointInterface</hardwareInterface>
    </joint>
    <actuator name="motor1">
      <hardwareInterface>hardware_interface/PositionJointInterface</hardwareInterface>
      <mechanicalReduction>1</mechanicalReduction>
    </actuator>
  </transmission>
  <transmission name="tran1">
    <type>transmission_interface/SimpleTransmission</type>
    <joint name="joint5">
      <hardwareInterface>hardware_interface/PositionJointInterface</hardwareInterface>
    </joint>
    <actuator name="motor1">
      <hardwareInterface>hardware_interface/PositionJointInterface</hardwareInterface>
      <mechanicalReduction>1</mechanicalReduction>
    </actuator>
  </transmission>
  <transmission name="tran1">
    <type>transmission_interface/SimpleTransmission</type>
    <joint name="finger_joint1">
      <hardwareInterface>hardware_interface/PositionJointInterface</hardwareInterface>
    </joint>
    <actuator name="motor1">
      <hardwareInterface>hardware_interface/PositionJointInterface</hardwareInterface>
      <mechanicalReduction>1</mechanicalReduction>
    </actuator>
  </transmission>
  <transmission name="tran1">
    <type>transmission_interface/SimpleTransmission</type>
    <joint name="finger_joint2">
      <hardwareInterface>hardware_interface/PositionJointInterface</hardwareInterface>
    </joint>
    <actuator name="motor1">
      <hardwareInterface>hardware_interface/PositionJointInterface</hardwareInterface>
      <mechanicalReduction>1</mechanicalReduction>
    </actuator>
  </transmission>
  <!-- ros_control plugin -->
  <gazebo>
    <plugin filename="libgazebo_ros_control.so" name="gazebo_ros_control">
      <robotNamespace>/bw_robot_arm</robotNamespace>
    </plugin>
  </gazebo>
</robot>

